Workbook

Sheet Students Number
A1: Veritas | B1: PTK | C1: SJK(C) Tung hua | D1: SJK(C) Chung hua | E1: SJK(C) Chung Sing | F1: SJK(C) Su Lai | G1: SMK Sacred Heart | H1: Woodlands | I1: SJK(C) Thai Kwang | J1: Suspened | K1: Total
A2: =COUNTIFS('CBK Students'!C:C, "Active", 'CBK Students'!G:G, "Veritas") -> 138 | B2: =COUNTIFS('CBK Students'!C:C, "Active", 'CBK Students'!G:G, "Pusat Tuisyen Kampus") -> 6 | C2: =COUNTIFS('CBK Students'!C:C, "Active", 'CBK Students'!G:G, "SJK(C) Tung Hua") -> 19 | D2: =COUNTIFS('CBK Students'!C:C, "Active", 'CBK Students'!G:G, "SJK(C) Chung Hua") -> 6 | E2: =COUNTIFS('CBK Students'!C:C, "Active", 'CBK Students'!G:G, "SJK(C) Chung Sing") -> 6 | F2: =COUNTIFS('CBK Students'!C:C, "Active", 'CBK Students'!G:G, "SJK(C) Su Lai") -> 10 | G2: =COUNTIFS('CBK Students'!C:C, "Active", 'CBK Students'!G:G, "SMK Sacred Heart") -> 4 | H2: =COUNTIFS('CBK Students'!C:C, "Active", 'CBK Students'!G:G, "Woodlands") -> 3 | I2: =COUNTIFS('CBK Students'!C:C, "Active", 'CBK Students'!G:G, "SJK(C) Thai Kwang") -> 37 | J2: =COUNTIFS('CBK Students'!C:C, "Suspended") -> 7 | K2: =SUM(A2:I2) -> 229
A4: Monday | B4: Wednesday | C4: Thursday | D4: Saturday (9-10) | E4: Saturday (10-11) | F4: Saturday (11-12) | G4: Saturday (2-3) | H4: Saturday (3-4) | I4: Saturday (4-5)
A5: =COUNTIFS('CBK Students'!F:F, "1 Mon 7:30-8:30pm",'CBK Students'!C:C, "Active") -> 20 | B5: =COUNTIFS('CBK Students'!F:F, "2 Wed 7:30-8:30pm",'CBK Students'!C:C, "Active") -> 24 | C5: =COUNTIFS('CBK Students'!F:F, "3 Thu 7:30-8:30pm",'CBK Students'!C:C, "Active") -> 2 | D5: =COUNTIFS('CBK Students'!F:F, "4 Sat 9:00-10:00am",'CBK Students'!C:C, "Active") -> 12 | E5: =COUNTIFS('CBK Students'!F:F, "5 Sat 10:00-11:00am",'CBK Students'!C:C, "Active") -> 15 | F5: =COUNTIFS('CBK Students'!F:F, "6 Sat 11:00-12:00pm",'CBK Students'!C:C, "Active") -> 23 | G5: =COUNTIFS('CBK Students'!F:F, "7 Sat 2:00-3:00pm",'CBK Students'!C:C, "Active") -> 21 | H5: =COUNTIFS('CBK Students'!F:F, "8 Sat 3:00-4:00pm",'CBK Students'!C:C, "Active") -> 8 | I5: =COUNTIFS('CBK Students'!F:F, "9 Sat 4:00-5:00pm",'CBK Students'!C:C, "Active") -> 13
A9: Month (2026) | B9: March | C9: April | D9: May | E9: Jun | F9: Jul | G9: Aug | H9: Sep | I9: Oct | J9: Nov | K9: Dec
A10: Current Student Number | B10: =COUNTIFS( 'CBK Students'!D:D,"<"&DATE(2026,4,1), 'CBK Students'!C:C,"<>Inactive", 'CBK Students'!C:C,"<>Suspended" ) -> 187 | C10: =COUNTIFS( 'CBK Students'!D:D,"<"&DATE(2026,5,1), 'CBK Students'!C:C,"<>Inactive", 'CBK Students'!C:C,"<>Suspended" ) -> 229 | D10: =COUNTIFS( 'CBK Students'!D:D,"<"&DATE(2026,6,1), 'CBK Students'!C:C,"<>Inactive", 'CBK Students'!C:C,"<>Suspended" ) -> 229 | E10: =COUNTIFS( 'CBK Students'!D:D,"<"&DATE(2026,7,1), 'CBK Students'!C:C,"<>Inactive", 'CBK Students'!C:C,"<>Suspended" ) -> 229 | F10: =COUNTIFS( 'CBK Students'!D:D,"<"&DATE(2026,8,1), 'CBK Students'!C:C,"<>Inactive", 'CBK Students'!C:C,"<>Suspended" ) -> 229 | G10: =COUNTIFS( 'CBK Students'!D:D,"<"&DATE(2026,9,1), 'CBK Students'!C:C,"<>Inactive", 'CBK Students'!C:C,"<>Suspended" ) -> 229 | H10: =COUNTIFS( 'CBK Students'!D:D,"<"&DATE(2026,10,1), 'CBK Students'!C:C,"<>Inactive", 'CBK Students'!C:C,"<>Suspended" ) -> 229 | I10: =COUNTIFS( 'CBK Students'!D:D,"<"&DATE(2026,11,1), 'CBK Students'!C:C,"<>Inactive", 'CBK Students'!C:C,"<>Suspended" ) -> 229 | J10: =COUNTIFS( 'CBK Students'!D:D,"<"&DATE(2026,12,1), 'CBK Students'!C:C,"<>Inactive", 'CBK Students'!C:C,"<>Suspended" ) -> 229 | K10: =COUNTIFS( 'CBK Students'!D:D,"<"&DATE(2027,1,1), 'CBK Students'!C:C,"<>Inactive", 'CBK Students'!C:C,"<>Suspended" ) -> 229
A11: New Students | B11: =COUNTIFS('CBK Students'!D:D,">="&DATE(2026,3,1),'CBK Students'!D:D,"<"&DATE(2026,4,1)) -> 20 | C11: =COUNTIFS('CBK Students'!D:D,">="&DATE(2026,4,1),'CBK Students'!D:D,"<"&DATE(2026,5,1)) -> 44 | D11: =COUNTIFS('CBK Students'!D:D,">="&DATE(2026,5,1),'CBK Students'!D:D,"<"&DATE(2026,6,1)) -> 0 | E11: =COUNTIFS('CBK Students'!D:D,">="&DATE(2026,6,1),'CBK Students'!D:D,"<"&DATE(2026,7,1)) -> 0 | F11: =COUNTIFS('CBK Students'!D:D,">="&DATE(2026,7,1),'CBK Students'!D:D,"<"&DATE(2026,8,1)) -> 0 | G11: =COUNTIFS('CBK Students'!D:D,">="&DATE(2026,8,1),'CBK Students'!D:D,"<"&DATE(2026,9,1)) -> 0 | H11: =COUNTIFS('CBK Students'!D:D,">="&DATE(2026,9,1),'CBK Students'!D:D,"<"&DATE(2026,10,1)) -> 0 | I11: =COUNTIFS('CBK Students'!D:D,">="&DATE(2026,10,1),'CBK Students'!D:D,"<"&DATE(2026,11,1)) -> 0 | J11: =COUNTIFS('CBK Students'!D:D,">="&DATE(2026,11,1),'CBK Students'!D:D,"<"&DATE(2026,12,1)) -> 0 | K11: =COUNTIFS('CBK Students'!D:D,">="&DATE(2026,12,1),'CBK Students'!D:D,"<"&DATE(2027,1,1)) -> 0
A12: Student Quit | B12: =COUNTIFS('CBK Students'!E:E,">="&DATE(2026,3,1),'CBK Students'!E:E,"<"&DATE(2026,4,1)) -> 10 | C12: =COUNTIFS('CBK Students'!E:E,">="&DATE(2026,4,1),'CBK Students'!E:E,"<"&DATE(2026,5,1)) -> 4 | D12: =COUNTIFS('CBK Students'!E:E,">="&DATE(2026,5,1),'CBK Students'!E:E,"<"&DATE(2026,6,1)) -> 0 | E12: =COUNTIFS('CBK Students'!E:E,">="&DATE(2026,6,1),'CBK Students'!E:E,"<"&DATE(2026,7,1)) -> 0 | F12: =COUNTIFS('CBK Students'!E:E,">="&DATE(2026,7,1),'CBK Students'!E:E,"<"&DATE(2026,8,1)) -> 0 | G12: =COUNTIFS('CBK Students'!E:E,">="&DATE(2026,8,1),'CBK Students'!E:E,"<"&DATE(2026,9,1)) -> 0 | H12: =COUNTIFS('CBK Students'!E:E,">="&DATE(2026,9,1),'CBK Students'!E:E,"<"&DATE(2026,10,1)) -> 0 | I12: =COUNTIFS('CBK Students'!E:E,">="&DATE(2026,10,1),'CBK Students'!E:E,"<"&DATE(2026,11,1)) -> 0 | J12: =COUNTIFS('CBK Students'!E:E,">="&DATE(2026,11,1),'CBK Students'!E:E,"<"&DATE(2026,12,1)) -> 0 | K12: =COUNTIFS('CBK Students'!E:E,">="&DATE(2026,12,1),'CBK Students'!E:E,"<"&DATE(2027,1,1)) -> 0
B14: Marcus Tiang Tew Hann | C14: Gavin Tiong Hai Liang
B15: Mercury Wong Lun Chein | C15: Jee Wyn Swan
B16: Adrian Tong Duo You | C16: Kathlyn Wong
B17: Adam Naqiudin Ahmad bin Saziran | C17: Louis Wong
B18: Zion Shi Nian Xi
B19: David Kee Zu Guo
B20: Jolene Kee Zu Lin
B21: Wong Jing Shang
B22: Wong Jing Yu
B23: Wong Jing Xiu

Sheet CBK Students
A1: No | B1: Student Name | C1: Status | D1: Date Active | E1: Date Deactivated | F1: Timeslot | G1: Location | H1: Mentor | I1: Date Activated | J1: Current Course | K1: Reflected | L1: Issue | M1: Week Since Course Started | N1: Previous Course | O1: Remark | P1: History Log | Q1: No Problem | R1: Estimated End | S1: Jun Showcase | T1: Whatsapp Group Name | U1: 2025 Update # | V1: Jan Update # | W1: Feb Update # | X1: Mar Update | Y1: Apr Update | Z1: # | AA1: 2026 Update #
A2: 36 | B2: Jane Wong Xin Yue | C2: Active | D2: 44568 | F2: 1 Mon 7:30-8:30pm | G2: Veritas | H2: Damian | I2: 45859 | J2: Game Development | K2: TRUE | M2: =INT((TODAY() - I2) / 7) -> 38 | O2: =IFERROR(__xludf.DUMMYFUNCTION("IFERROR( TEXT( MAX(FILTER(Remark!A:A, TRIM(Remark!B:B) = TRIM(B2))), ""dd/mm/yyyy"" ) & "" - "" & FILTER( Remark!C:C, TRIM(Remark!B:B) = TRIM(B2), Remark!A:A = MAX(FILTER(Remark!A:A, TRIM(Remark!B:B) = TRIM(B2))) ), """" )"),"") | P2: =IFERROR(__xludf.DUMMYFUNCTION("TEXTJOIN(CHAR(10), TRUE, IFERROR( FILTER(TEXT(Remark!A:A, ""dd/mm/yyyy"") & "" - "" & Remark!C:C, TRIM(Remark!B:B) = TRIM(B2)), """" ))"),"") | Q2: =IFERROR(__xludf.DUMMYFUNCTION("IFERROR( FILTER( Remark!D:D, Remark!A:A = MAX(FILTER(Remark!A:A, TRIM(Remark!B:B) = TRIM(B2))) ), """" )"),"") | R2: =IFS(M2<=30, "Learning", AND(M2>30, M2<=40),"Starting Final Project", M2>40, "Prepare for Showcase") -> Starting Final Project | T2: Joanna/Jane/Janice - Chumbaka | U2: 2 | V2: 1 | W2: 1 | X2: 1 | Y2: 1 | AA2: =sum(V2:Z2) -> 4
A3: 99 | B3: Aidan Siaw Min Le | C3: Active | D3: 44869 | F3: 1 Mon 7:30-8:30pm | G3: Veritas | H3: Damian | I3: 45717 | J3: 3D Design for AR and VR | K3: TRUE | L3: Changing Timeslot | M3: =INT((TODAY() - I3) / 7) -> 59 | O3: =IFERROR(__xludf.DUMMYFUNCTION("IFERROR( TEXT( MAX(FILTER(Remark!A:A, TRIM(Remark!B:B) = TRIM(B3))), ""dd/mm/yyyy"" ) & "" - "" & FILTER( Remark!C:C, TRIM(Remark!B:B) = TRIM(B3), Remark!A:A = MAX(FILTER(Remark!A:A, TRIM(Remark!B:B) = TRIM(B3))) ), """" )"),"24/09/2025 - [Caleb] It was a bit dragging because the method inside the LMS no longer works and now requires a subscription fee. Aidan is having issues with using his phone in class. In my view, the mentor should have informed the parents earlier, even t"&"hough we are already working on helping him improve this.") -> 24/09/2025 - [Caleb] It was a bit dragging because the method inside the LMS no longer works and now requires a subscription fee. Aidan is having issues with using his phone in class. In my view, the mentor should have informed the parents earlier, even though we are already working on helping him improve this. | P3: =IFERROR(__xludf.DUMMYFUNCTION("TEXTJOIN(CHAR(10), TRUE, IFERROR( FILTER(TEXT(Remark!A:A, ""dd/mm/yyyy"") & "" - "" & Remark!C:C, TRIM(Remark!B:B) = TRIM(B3)), """" ))"),"24/09/2025 - [Caleb] It was a bit dragging because the method inside the LMS no longer works and now requires a subscription fee. Aidan is having issues with using his phone in class. In my view, the mentor should have informed the parents earlier, even t"&"hough we are already working on helping him improve this.") -> 24/09/2025 - [Caleb] It was a bit dragging because the method inside the LMS no longer works and now requires a subscription fee. Aidan is having issues with using his phone in class. In my view, the mentor should have informed the parents earlier, even though we are already working on helping him improve this. | Q3: =IFERROR(__xludf.DUMMYFUNCTION("IFERROR( FILTER( Remark!D:D, Remark!A:A = MAX(FILTER(Remark!A:A, TRIM(Remark!B:B) = TRIM(B3))) ), """" )"),"No") -> No | R3: =IFS(M3<=30, "Learning", AND(M3>30, M3<=40),"Starting Final Project", M3>40, "Prepare for Showcase") -> Prepare for Showcase | S3: TRUE | T3: Aidan Siaw - CHUMBAKA | U3: 2 | V3: 1 | X3: 1 | Y3: 1 | AA3: =sum(V3:Z3) -> 3
A4: 271 | B4: Elina Kong Zhe En | C4: Active | D4: 45503 | F4: 1 Mon 7:30-8:30pm | G4: Veritas | H4: Damian | I4: 45960 | J4: Game Development | K4: TRUE | L4: Changing Timeslot | M4: =INT((TODAY() - I4) / 7) -> 24 | O4: =IFERROR(__xludf.DUMMYFUNCTION("IFERROR( TEXT( MAX(FILTER(Remark!A:A, TRIM(Remark!B:B) = TRIM(B4))), ""dd/mm/yyyy"" ) & "" - "" & FILTER( Remark!C:C, TRIM(Remark!B:B) = TRIM(B4), Remark!A:A = MAX(FILTER(Remark!A:A, TRIM(Remark!B:B) = TRIM(B4))) ), """" )"),"") | P4: =IFERROR(__xludf.DUMMYFUNCTION("TEXTJOIN(CHAR(10), TRUE, IFERROR( FILTER(TEXT(Remark!A:A, ""dd/mm/yyyy"") & "" - "" & Remark!C:C, TRIM(Remark!B:B) = TRIM(B4)), """" ))"),"") | Q4: =IFERROR(__xludf.DUMMYFUNCTION("IFERROR( FILTER( Remark!D:D, Remark!A:A = MAX(FILTER(Remark!A:A, TRIM(Remark!B:B) = TRIM(B4))) ), """" )"),"") | R4: =IFS(M4<=30, "Learning", AND(M4>30, M4<=40),"Starting Final Project", M4>40, "Prepare for Showcase") -> Learning | T4: Elina Kong(TH) - Chumbaka | U4: 1 | W4: 1 | X4: 2 | Y4: 1 | AA4: =sum(V4:Z4) -> 4
A5: 273 | B5: Eileen Wong Hui Qing | C5: Active | D5: 45504 | F5: 1 Mon 7:30-8:30pm | G5: Veritas | H5: Damian | I5: 45967 | J5: Game Development | K5: TRUE | L5: Changing Timeslot, Changing Mentor | M5: =INT((TODAY() - I5) / 7) -> 23 | O5: =IFERROR(__xludf.DUMMYFUNCTION("IFERROR( TEXT( MAX(FILTER(Remark!A:A, TRIM(Remark!B:B) = TRIM(B5))), ""dd/mm/yyyy"" ) & "" - "" & FILTER( Remark!C:C, TRIM(Remark!B:B) = TRIM(B5), Remark!A:A = MAX(FILTER(Remark!A:A, TRIM(Remark!B:B) = TRIM(B5))) ), """" )"),"") | P5: =IFERROR(__xludf.DUMMYFUNCTION("TEXTJOIN(CHAR(10), TRUE, IFERROR( FILTER(TEXT(Remark!A:A, ""dd/mm/yyyy"") & "" - "" & Remark!C:C, TRIM(Remark!B:B) = TRIM(B5)), """" ))"),"") | Q5: =IFERROR(__xludf.DUMMYFUNCTION("IFERROR( FILTER( Remark!D:D, Remark!A:A = MAX(FILTER(Remark!A:A, TRIM(Remark!B:B) = TRIM(B5))) ), """" )"),"") | R5: =IFS(M5<=30, "Learning", AND(M5>30, M5<=40),"Starting Final Project", M5>40, "Prepare for Showcase") -> Learning | T5: Eileen/Eunice (TH) - Chumbaka | U5: 1 | V5: 1 | W5: 1 | X5: 1 | Y5: 1 | AA5: =sum(V5:Z5) -> 4
A6: 132 | B6: Jabez Huan Ngieng Hung | C6: Active | D6: 45083 | F6: 1 Mon 7:30-8:30pm | G6: Veritas | H6: Enouch | I6: 45768 | J6: Physical Computing | K6: TRUE | M6: =INT((TODAY() - I6) / 7) -> 51 | O6: =IFERROR(__xludf.DUMMYFUNCTION("IFERROR( TEXT( MAX(FILTER(Remark!A:A, TRIM(Remark!B:B) = TRIM(B6))), ""dd/mm/yyyy"" ) & "" - "" & FILTER( Remark!C:C, TRIM(Remark!B:B) = TRIM(B6), Remark!A:A = MAX(FILTER(Remark!A:A, TRIM(Remark!B:B) = TRIM(B6))) ), """" )"),"08/10/2025 - [Caleb] The student has a special condition, which causes a slower learning pace compared to other students. However, there has been significant improvement — previously, it was difficult for him to express his needs, but now he is able to co"&"mmunicate more clearly. Mentor is advised to continue challenging him to maintain consistent progress and to set a clear timeline each time he moves on to a new page.") -> 08/10/2025 - [Caleb] The student has a special condition, which causes a slower learning pace compared to other students. However, there has been significant improvement — previously, it was difficult for him to express his needs, but now he is able to communicate more clearly. Mentor is advised to continue challenging him to maintain consistent progress and to set a clear timeline each time he moves on to a new page. | P6: =IFERROR(__xludf.DUMMYFUNCTION("TEXTJOIN(CHAR(10), TRUE, IFERROR( FILTER(TEXT(Remark!A:A, ""dd/mm/yyyy"") & "" - "" & Remark!C:C, TRIM(Remark!B:B) = TRIM(B6)), """" ))"),"08/10/2025 - [Caleb] The student has a special condition, which causes a slower learning pace compared to other students. However, there has been significant improvement — previously, it was difficult for him to express his needs, but now he is able to co"&"mmunicate more clearly. Mentor is advised to continue challenging him to maintain consistent progress and to set a clear timeline each time he moves on to a new page.") -> 08/10/2025 - [Caleb] The student has a special condition, which causes a slower learning pace compared to other students. However, there has been significant improvement — previously, it was difficult for him to express his needs, but now he is able to communicate more clearly. Mentor is advised to continue challenging him to maintain consistent progress and to set a clear timeline each time he moves on to a new page. | Q6: =IFERROR(__xludf.DUMMYFUNCTION("IFERROR( FILTER( Remark!D:D, Remark!A:A = MAX(FILTER(Remark!A:A, TRIM(Remark!B:B) = TRIM(B6))) ), """" )"),"Yes") -> Yes | R6: =IFS(M6<=30, "Learning", AND(M6>30, M6<=40),"Starting Final Project", M6>40, "Prepare for Showcase") -> Prepare for Showcase | S6: TRUE | T6: Jabez - CHUMBAKA | U6: 3 | X6: 1 | AA6: =sum(V6:Z6) -> 1
A7: 186 | B7: Lucas Lau Yee Ming | C7: Active | D7: 45201 | F7: 1 Mon 7:30-8:30pm | G7: Veritas | H7: Enouch | I7: 45542 | J7: Physical Computing | K7: TRUE | M7: =INT((TODAY() - I7) / 7) -> 84 | O7: =IFERROR(__xludf.DUMMYFUNCTION("IFERROR( TEXT( MAX(FILTER(Remark!A:A, TRIM(Remark!B:B) = TRIM(B7))), ""dd/mm/yyyy"" ) & "" - "" & FILTER( Remark!C:C, TRIM(Remark!B:B) = TRIM(B7), Remark!A:A = MAX(FILTER(Remark!A:A, TRIM(Remark!B:B) = TRIM(B7))) ), """" )"),"") | P7: =IFERROR(__xludf.DUMMYFUNCTION("TEXTJOIN(CHAR(10), TRUE, IFERROR( FILTER(TEXT(Remark!A:A, ""dd/mm/yyyy"") & "" - "" & Remark!C:C, TRIM(Remark!B:B) = TRIM(B7)), """" ))"),"") | Q7: =IFERROR(__xludf.DUMMYFUNCTION("IFERROR( FILTER( Remark!D:D, Remark!A:A = MAX(FILTER(Remark!A:A, TRIM(Remark!B:B) = TRIM(B7))) ), """" )"),"") | R7: =IFS(M7<=30, "Learning", AND(M7>30, M7<=40),"Starting Final Project", M7>40, "Prepare for Showcase") -> Prepare for Showcase | S7: TRUE | T7: Lucas/Marcus - Chumbaka | U7: 4 | V7: 1 | X7: 1 | AA7: =sum(V7:Z7) -> 2
A8: 274 | B8: Clexter Cheng Kwong Yong | C8: Active | D8: 45509 | F8: 1 Mon 7:30-8:30pm | G8: Veritas | H8: Enouch | I8: 45642 | J8: Physical Computing | K8: TRUE | M8: =INT((TODAY() - I8) / 7) -> 69 | O8: =IFERROR(__xludf.DUMMYFUNCTION("IFERROR( TEXT( MAX(FILTER(Remark!A:A, TRIM(Remark!B:B) = TRIM(B8))), ""dd/mm/yyyy"" ) & "" - "" & FILTER( Remark!C:C, TRIM(Remark!B:B) = TRIM(B8), Remark!A:A = MAX(FILTER(Remark!A:A, TRIM(Remark!B:B) = TRIM(B8))) ), """" )"),"") | P8: =IFERROR(__xludf.DUMMYFUNCTION("TEXTJOIN(CHAR(10), TRUE, IFERROR( FILTER(TEXT(Remark!A:A, ""dd/mm/yyyy"") & "" - "" & Remark!C:C, TRIM(Remark!B:B) = TRIM(B8)), """" ))"),"") | Q8: =IFERROR(__xludf.DUMMYFUNCTION("IFERROR( FILTER( Remark!D:D, Remark!A:A = MAX(FILTER(Remark!A:A, TRIM(Remark!B:B) = TRIM(B8))) ), """" )"),"") | R8: =IFS(M8<=30, "Learning", AND(M8>30, M8<=40),"Starting Final Project", M8>40, "Prepare for Showcase") -> Prepare for Showcase | S8: TRUE | T8: Clexter/Hillary - Chumbaka | U8: 6 | V8: 1 | X8: 1 | Y8: 1 | AA8: =sum(V8:Z8) -> 3
A9: 275 | B9: Hillary Yong | C9: Active | D9: 45509 | F9: 1 Mon 7:30-8:30pm | G9: Veritas | H9: Enouch | I9: 45670 | J9: Physical Computing | K9: TRUE | M9: =INT((TODAY() - I9) / 7) -> 65 | O9: =IFERROR(__xludf.DUMMYFUNCTION("IFERROR( TEXT( MAX(FILTER(Remark!A:A, TRIM(Remark!B:B) = TRIM(B9))), ""dd/mm/yyyy"" ) & "" - "" & FILTER( Remark!C:C, TRIM(Remark!B:B) = TRIM(B9), Remark!A:A = MAX(FILTER(Remark!A:A, TRIM(Remark!B:B) = TRIM(B9))) ), """" )"),"") | P9: =IFERROR(__xludf.DUMMYFUNCTION("TEXTJOIN(CHAR(10), TRUE, IFERROR( FILTER(TEXT(Remark!A:A, ""dd/mm/yyyy"") & "" - "" & Remark!C:C, TRIM(Remark!B:B) = TRIM(B9)), """" ))"),"") | Q9: =IFERROR(__xludf.DUMMYFUNCTION("IFERROR( FILTER( Remark!D:D, Remark!A:A = MAX(FILTER(Remark!A:A, TRIM(Remark!B:B) = TRIM(B9))) ), """" )"),"") | R9: =IFS(M9<=30, "Learning", AND(M9>30, M9<=40),"Starting Final Project", M9>40, "Prepare for Showcase") -> Prepare for Showcase | S9: TRUE | T9: Clexter/Hillary - Chumbaka | U9: 4 | V9: 1 | X9: 1 | Y9: 1 | AA9: =sum(V9:Z9) -> 3
A10: 342 | B10: Janice Wong Xiao Yue | C10: Active | D10: 45740 | F10: 1 Mon 7:30-8:30pm | G10: Veritas | H10: Evelyn | I10: 46125 | J10: Creative Computing | K10: TRUE | L10: Changing Timeslot | M10: =INT((TODAY() - I10) / 7) -> 0 | N10: Digital Animation Showcase | O10: =IFERROR(__xludf.DUMMYFUNCTION("IFERROR( TEXT( MAX(FILTER(Remark!A:A, TRIM(Remark!B:B) = TRIM(B10))), ""dd/mm/yyyy"" ) & "" - "" & FILTER( Remark!C:C, TRIM(Remark!B:B) = TRIM(B10), Remark!A:A = MAX(FILTER(Remark!A:A, TRIM(Remark!B:B) = TRIM(B10))) ), """" )"),"") | P10: =IFERROR(__xludf.DUMMYFUNCTION("TEXTJOIN(CHAR(10), TRUE, IFERROR( FILTER(TEXT(Remark!A:A, ""dd/mm/yyyy"") & "" - "" & Remark!C:C, TRIM(Remark!B:B) = TRIM(B10)), """" ))"),"") | Q10: =IFERROR(__xludf.DUMMYFUNCTION("IFERROR( FILTER( Remark!D:D, Remark!A:A = MAX(FILTER(Remark!A:A, TRIM(Remark!B:B) = TRIM(B10))) ), """" )"),"") | R10: =IFS(M10<=30, "Learning", AND(M10>30, M10<=40),"Starting Final Project", M10>40, "Prepare for Showcase") -> Learning | S10: TRUE | T10: Joanna/Jane/Janice - Chumbaka | U10: 2 | V10: 1 | X10: 1 | Y10: 1 | AA10: =sum(V10:Z10) -> 3
A11: 394 | B11: Kyan Ling Tian Xiang | C11: Active | D11: 45869 | F11: 1 Mon 7:30-8:30pm | G11: Veritas | H11: Evelyn | I11: 46055 | J11: Creative Computing | K11: TRUE | M11: =INT((TODAY() - I11) / 7) -> 10 | N11: Mobile Coding Showcase | O11: =IFERROR(__xludf.DUMMYFUNCTION("IFERROR( TEXT( MAX(FILTER(Remark!A:A, TRIM(Remark!B:B) = TRIM(B11))), ""dd/mm/yyyy"" ) & "" - "" & FILTER( Remark!C:C, TRIM(Remark!B:B) = TRIM(B11), Remark!A:A = MAX(FILTER(Remark!A:A, TRIM(Remark!B:B) = TRIM(B11))) ), """" )"),"") | P11: =IFERROR(__xludf.DUMMYFUNCTION("TEXTJOIN(CHAR(10), TRUE, IFERROR( FILTER(TEXT(Remark!A:A, ""dd/mm/yyyy"") & "" - "" & Remark!C:C, TRIM(Remark!B:B) = TRIM(B11)), """" ))"),"") | Q11: =IFERROR(__xludf.DUMMYFUNCTION("IFERROR( FILTER( Remark!D:D, Remark!A:A = MAX(FILTER(Remark!A:A, TRIM(Remark!B:B) = TRIM(B11))) ), """" )"),"") | R11: =IFS(M11<=30, "Learning", AND(M11>30, M11<=40),"Starting Final Project", M11>40, "Prepare for Showcase") -> Learning | S11: TRUE | T11: Kyan Ling - Chumbaka | U11: 6 | V11: 1 | W11: 1 | X11: 1 | AA11: =sum(V11:Z11) -> 3
A12: 467 | B12: Gabriel Hung Tuan Zhi | C12: Active | D12: 46083 | F12: 1 Mon 7:30-8:30pm | G12: Veritas | H12: Evelyn | I12: 46090 | J12: Creative Computing | K12: FALSE | M12: =INT((TODAY() - I12) / 7) -> 5 | P12: =IFERROR(__xludf.DUMMYFUNCTION("TEXTJOIN(CHAR(10), TRUE, IFERROR( FILTER(TEXT(Remark!A:A, ""dd/mm/yyyy"") & "" - "" & Remark!C:C, TRIM(Remark!B:B) = TRIM(B12)), """" ))"),"") | Q12: =IFERROR(__xludf.DUMMYFUNCTION("IFERROR( FILTER( Remark!D:D, Remark!A:A = MAX(FILTER(Remark!A:A, TRIM(Remark!B:B) = TRIM(B12))) ), """" )"),"") | R12: =IFS(M12<=30, "Learning", AND(M12>30, M12<=40),"Starting Final Project", M12>40, "Prepare for Showcase") -> Learning | S12: FALSE | T12: Gabriel Hung - Chumbaka | X12: 1 | Y12: 1 | AA12: =sum(V12:Z12) -> 2
A13: 391 | B13: Josh Ting Sie Jun | C13: Active | D13: 45845 | F13: 1 Mon 7:30-8:30pm | G13: Veritas | H13: Kerry | I13: 45845 | J13: Mobile Coding | K13: TRUE | M13: =INT((TODAY() - I13) / 7) -> 40 | O13: =IFERROR(__xludf.DUMMYFUNCTION("IFERROR( TEXT( MAX(FILTER(Remark!A:A, TRIM(Remark!B:B) = TRIM(B13))), ""dd/mm/yyyy"" ) & "" - "" & FILTER( Remark!C:C, TRIM(Remark!B:B) = TRIM(B13), Remark!A:A = MAX(FILTER(Remark!A:A, TRIM(Remark!B:B) = TRIM(B13))) ), """" )"),"") | P13: =IFERROR(__xludf.DUMMYFUNCTION("TEXTJOIN(CHAR(10), TRUE, IFERROR( FILTER(TEXT(Remark!A:A, ""dd/mm/yyyy"") & "" - "" & Remark!C:C, TRIM(Remark!B:B) = TRIM(B13)), """" ))"),"") | Q13: =IFERROR(__xludf.DUMMYFUNCTION("IFERROR( FILTER( Remark!D:D, Remark!A:A = MAX(FILTER(Remark!A:A, TRIM(Remark!B:B) = TRIM(B13))) ), """" )"),"") | R13: =IFS(M13<=30, "Learning", AND(M13>30, M13<=40),"Starting Final Project", M13>40, "Prepare for Showcase") -> Starting Final Project | T13: Josh Ting - Chumbaka | U13: 6 | V13: 1 | X13: 1 | Y13: 1 | AA13: =sum(V13:Z13) -> 3
A14: 436 | B14: Eeson Wong bin Mohammad Hisham | C14: Active | D14: 46036 | F14: 1 Mon 7:30-8:30pm | G14: Veritas | H14: Kerry | I14: 46034 | J14: Mobile Coding | K14: FALSE | M14: =INT((TODAY() - I14) / 7) -> 13 | O14: =IFERROR(__xludf.DUMMYFUNCTION("IFERROR( TEXT( MAX(FILTER(Remark!A:A, TRIM(Remark!B:B) = TRIM(B14))), ""dd/mm/yyyy"" ) & "" - "" & FILTER( Remark!C:C, TRIM(Remark!B:B) = TRIM(B14), Remark!A:A = MAX(FILTER(Remark!A:A, TRIM(Remark!B:B) = TRIM(B14))) ), """" )"),"") | P14: =IFERROR(__xludf.DUMMYFUNCTION("TEXTJOIN(CHAR(10), TRUE, IFERROR( FILTER(TEXT(Remark!A:A, ""dd/mm/yyyy"") & "" - "" & Remark!C:C, TRIM(Remark!B:B) = TRIM(B14)), """" ))"),"") | Q14: =IFERROR(__xludf.DUMMYFUNCTION("IFERROR( FILTER( Remark!D:D, Remark!A:A = MAX(FILTER(Remark!A:A, TRIM(Remark!B:B) = TRIM(B14))) ), """" )"),"") | R14: =IFS(M14<=30, "Learning", AND(M14>30, M14<=40),"Starting Final Project", M14>40, "Prepare for Showcase") -> Learning | T14: Eeson Wong - Chumbaka | W14: 1 | X14: 1 | Y14: 2 | AA14: =sum(V14:Z14) -> 4
A15: 446 | B15: Isaac Lau Li Sheng | C15: Active | D15: 46056 | F15: 1 Mon 7:30-8:30pm | G15: Veritas | H15: Kerry | I15: 46055 | J15: Mobile Coding | K15: FALSE | M15: =INT((TODAY() - I15) / 7) -> 10 | O15: =IFERROR(__xludf.DUMMYFUNCTION("IFERROR( TEXT( MAX(FILTER(Remark!A:A, TRIM(Remark!B:B) = TRIM(B15))), ""dd/mm/yyyy"" ) & "" - "" & FILTER( Remark!C:C, TRIM(Remark!B:B) = TRIM(B15), Remark!A:A = MAX(FILTER(Remark!A:A, TRIM(Remark!B:B) = TRIM(B15))) ), """" )"),"") | P15: =IFERROR(__xludf.DUMMYFUNCTION("TEXTJOIN(CHAR(10), TRUE, IFERROR( FILTER(TEXT(Remark!A:A, ""dd/mm/yyyy"") & "" - "" & Remark!C:C, TRIM(Remark!B:B) = TRIM(B15)), """" ))"),"") | Q15: =IFERROR(__xludf.DUMMYFUNCTION("IFERROR( FILTER( Remark!D:D, Remark!A:A = MAX(FILTER(Remark!A:A, TRIM(Remark!B:B) = TRIM(B15))) ), """" )"),"") | R15: =IFS(M15<=30, "Learning", AND(M15>30, M15<=40),"Starting Final Project", M15>40, "Prepare for Showcase") -> Learning | S15: FALSE | T15: Isaac Lau - Chumbaka | W15: 1 | X15: 3 | Y15: 2 | AA15: =sum(V15:Z15) -> 6
A16: 451 | B16: Yong Feng Kai | C16: Active | D16: 46062 | F16: 1 Mon 7:30-8:30pm | G16: Veritas | H16: Kerry | I16: 46055 | J16: Mobile Coding | K16: FALSE | M16: =INT((TODAY() - I16) / 7) -> 10 | O16: No | P16: =IFERROR(__xludf.DUMMYFUNCTION("TEXTJOIN(CHAR(10), TRUE, IFERROR( FILTER(TEXT(Remark!A:A, ""dd/mm/yyyy"") & "" - "" & Remark!C:C, TRIM(Remark!B:B) = TRIM(B16)), """" ))"),"24/02/2026 - So far, his progress is generally okay. He is progressing slightly slower as he is still learning to understand the instructions on the LMS. Mentor is guiding him step by step on how to read and interpret the instructions independently") -> 24/02/2026 - So far, his progress is generally okay. He is progressing slightly slower as he is still learning to understand the instructions on the LMS. Mentor is guiding him step by step on how to read and interpret the instructions independently | Q16: =IFERROR(__xludf.DUMMYFUNCTION("IFERROR( FILTER( Remark!D:D, Remark!A:A = MAX(FILTER(Remark!A:A, TRIM(Remark!B:B) = TRIM(B16))) ), """" )"),"No") -> No | R16: =IFS(M16<=30, "Learning", AND(M16>30, M16<=40),"Starting Final Project", M16>40, "Prepare for Showcase") -> Learning | S16: FALSE | T16: Feng Kai - Chumbaka | X16: 1 | Y16: 2 | AA16: =sum(V16:Z16) -> 3
A17: 41 | B17: Ezra Ling Sing Yi | C17: Active | D17: 44723 | F17: 1 Mon 7:30-8:30pm | G17: Veritas | H17: Lam | I17: 46027 | J17: AI with Python | K17: TRUE | L17: Changing Timeslot | M17: =INT((TODAY() - I17) / 7) -> 14 | O17: =IFERROR(__xludf.DUMMYFUNCTION("IFERROR( TEXT( MAX(FILTER(Remark!A:A, TRIM(Remark!B:B) = TRIM(B17))), ""dd/mm/yyyy"" ) & "" - "" & FILTER( Remark!C:C, TRIM(Remark!B:B) = TRIM(B17), Remark!A:A = MAX(FILTER(Remark!A:A, TRIM(Remark!B:B) = TRIM(B17))) ), """" )"),"") | P17: =IFERROR(__xludf.DUMMYFUNCTION("TEXTJOIN(CHAR(10), TRUE, IFERROR( FILTER(TEXT(Remark!A:A, ""dd/mm/yyyy"") & "" - "" & Remark!C:C, TRIM(Remark!B:B) = TRIM(B17)), """" ))"),"") | Q17: =IFERROR(__xludf.DUMMYFUNCTION("IFERROR( FILTER( Remark!D:D, Remark!A:A = MAX(FILTER(Remark!A:A, TRIM(Remark!B:B) = TRIM(B17))) ), """" )"),"") | R17: =IFS(M17<=30, "Learning", AND(M17>30, M17<=40),"Starting Final Project", M17>40, "Prepare for Showcase") -> Learning | T17: Ezra Ling - CHUMBAKA | U17: 2 | V17: 1 | Y17: 1 | AA17: =sum(V17:Z17) -> 2
A18: 9 | B18: Ting Zhi Xin | C18: Active | D18: 44532 | F18: 1 Mon 7:30-8:30pm | G18: Veritas | H18: Mandy | I18: 45922 | J18: 3D Design for AR and VR | K18: TRUE | M18: =INT((TODAY() - I18) / 7) -> 29 | O18: =IFERROR(__xludf.DUMMYFUNCTION("IFERROR( TEXT( MAX(FILTER(Remark!A:A, TRIM(Remark!B:B) = TRIM(B18))), ""dd/mm/yyyy"" ) & "" - "" & FILTER( Remark!C:C, TRIM(Remark!B:B) = TRIM(B18), Remark!A:A = MAX(FILTER(Remark!A:A, TRIM(Remark!B:B) = TRIM(B18))) ), """" )"),"") | P18: =IFERROR(__xludf.DUMMYFUNCTION("TEXTJOIN(CHAR(10), TRUE, IFERROR( FILTER(TEXT(Remark!A:A, ""dd/mm/yyyy"") & "" - "" & Remark!C:C, TRIM(Remark!B:B) = TRIM(B18)), """" ))"),"") | Q18: =IFERROR(__xludf.DUMMYFUNCTION("IFERROR( FILTER( Remark!D:D, Remark!A:A = MAX(FILTER(Remark!A:A, TRIM(Remark!B:B) = TRIM(B18))) ), """" )"),"") | R18: =IFS(M18<=30, "Learning", AND(M18>30, M18<=40),"Starting Final Project", M18>40, "Prepare for Showcase") -> Learning | T18: Zhi En/Zhi Xin - Chumbaka | U18: 4 | V18: 1 | Y18: 1 | AA18: =sum(V18:Z18) -> 2
A19: 187 | B19: Marcus Lau Yee Ho | C19: Active | D19: 45201 | F19: 1 Mon 7:30-8:30pm | G19: Veritas | H19: Mandy | I19: 46027 | J19: Coding and Algorithm | K19: TRUE | M19: =INT((TODAY() - I19) / 7) -> 14 | O19: =IFERROR(__xludf.DUMMYFUNCTION("IFERROR( TEXT( MAX(FILTER(Remark!A:A, TRIM(Remark!B:B) = TRIM(B19))), ""dd/mm/yyyy"" ) & "" - "" & FILTER( Remark!C:C, TRIM(Remark!B:B) = TRIM(B19), Remark!A:A = MAX(FILTER(Remark!A:A, TRIM(Remark!B:B) = TRIM(B19))) ), """" )"),"") | P19: =IFERROR(__xludf.DUMMYFUNCTION("TEXTJOIN(CHAR(10), TRUE, IFERROR( FILTER(TEXT(Remark!A:A, ""dd/mm/yyyy"") & "" - "" & Remark!C:C, TRIM(Remark!B:B) = TRIM(B19)), """" ))"),"") | Q19: =IFERROR(__xludf.DUMMYFUNCTION("IFERROR( FILTER( Remark!D:D, Remark!A:A = MAX(FILTER(Remark!A:A, TRIM(Remark!B:B) = TRIM(B19))) ), """" )"),"") | R19: =IFS(M19<=30, "Learning", AND(M19>30, M19<=40),"Starting Final Project", M19>40, "Prepare for Showcase") -> Learning | T19: Lucas/Marcus - Chumbaka | U19: 4 | X19: 1 | Y19: 1 | AA19: =sum(V19:Z19) -> 2
A20: 267 | B20: Oscar Khiew Jian Lyn | C20: Active | D20: 45503 | F20: 1 Mon 7:30-8:30pm | G20: Veritas | H20: Mandy | I20: 45960 | J20: Coding and Algorithm | K20: TRUE | M20: =INT((TODAY() - I20) / 7) -> 24 | O20: =IFERROR(__xludf.DUMMYFUNCTION("IFERROR( TEXT( MAX(FILTER(Remark!A:A, TRIM(Remark!B:B) = TRIM(B20))), ""dd/mm/yyyy"" ) & "" - "" & FILTER( Remark!C:C, TRIM(Remark!B:B) = TRIM(B20), Remark!A:A = MAX(FILTER(Remark!A:A, TRIM(Remark!B:B) = TRIM(B20))) ), """" )"),"") | P20: =IFERROR(__xludf.DUMMYFUNCTION("TEXTJOIN(CHAR(10), TRUE, IFERROR( FILTER(TEXT(Remark!A:A, ""dd/mm/yyyy"") & "" - "" & Remark!C:C, TRIM(Remark!B:B) = TRIM(B20)), """" ))"),"") | Q20: =IFERROR(__xludf.DUMMYFUNCTION("IFERROR( FILTER( Remark!D:D, Remark!A:A = MAX(FILTER(Remark!A:A, TRIM(Remark!B:B) = TRIM(B20))) ), """" )"),"") | R20: =IFS(M20<=30, "Learning", AND(M20>30, M20<=40),"Starting Final Project", M20>40, "Prepare for Showcase") -> Learning | T20: Oscar Khiew(TH) - Chumbaka | U20: 1 | X20: 1 | Y20: 1 | AA20: =sum(V20:Z20) -> 2
A21: 343 | B21: Jerry Yong Ching Hwa | C21: Active | D21: 45740 | F21: 1 Mon 7:30-8:30pm | G21: Veritas | H21: Mandy | I21: 45754 | J21: Coding and Algorithm | K21: TRUE | M21: =INT((TODAY() - I21) / 7) -> 53 | O21: =IFERROR(__xludf.DUMMYFUNCTION("IFERROR( TEXT( MAX(FILTER(Remark!A:A, TRIM(Remark!B:B) = TRIM(B21))), ""dd/mm/yyyy"" ) & "" - "" & FILTER( Remark!C:C, TRIM(Remark!B:B) = TRIM(B21), Remark!A:A = MAX(FILTER(Remark!A:A, TRIM(Remark!B:B) = TRIM(B21))) ), """" )"),"") | P21: =IFERROR(__xludf.DUMMYFUNCTION("TEXTJOIN(CHAR(10), TRUE, IFERROR( FILTER(TEXT(Remark!A:A, ""dd/mm/yyyy"") & "" - "" & Remark!C:C, TRIM(Remark!B:B) = TRIM(B21)), """" ))"),"") | Q21: =IFERROR(__xludf.DUMMYFUNCTION("IFERROR( FILTER( Remark!D:D, Remark!A:A = MAX(FILTER(Remark!A:A, TRIM(Remark!B:B) = TRIM(B21))) ), """" )"),"") | R21: =IFS(M21<=30, "Learning", AND(M21>30, M21<=40),"Starting Final Project", M21>40, "Prepare for Showcase") -> Prepare for Showcase | S21: TRUE | T21: Jerry Yong - Chumbaka | U21: 1 | V21: 1 | AA21: =sum(V21:Z21) -> 1
A22: 7 | B22: Ting Zhi En | C22: Active | D22: 44507 | F22: 2 Wed 7:30-8:30pm | G22: Veritas | H22: Chuan | I22: 45047 | J22: Embedded System | K22: TRUE | L22: Changing Timeslot | M22: =INT((TODAY() - I22) / 7) -> 154 | O22: =IFERROR(__xludf.DUMMYFUNCTION("IFERROR( TEXT( MAX(FILTER(Remark!A:A, TRIM(Remark!B:B) = TRIM(B22))), ""dd/mm/yyyy"" ) & "" - "" & FILTER( Remark!C:C, TRIM(Remark!B:B) = TRIM(B22), Remark!A:A = MAX(FILTER(Remark!A:A, TRIM(Remark!B:B) = TRIM(B22))) ), """" )"),"") | P22: =IFERROR(__xludf.DUMMYFUNCTION("TEXTJOIN(CHAR(10), TRUE, IFERROR( FILTER(TEXT(Remark!A:A, ""dd/mm/yyyy"") & "" - "" & Remark!C:C, TRIM(Remark!B:B) = TRIM(B22)), """" ))"),"") | Q22: =IFERROR(__xludf.DUMMYFUNCTION("IFERROR( FILTER( Remark!D:D, Remark!A:A = MAX(FILTER(Remark!A:A, TRIM(Remark!B:B) = TRIM(B22))) ), """" )"),"") | R22: =IFS(M22<=30, "Learning", AND(M22>30, M22<=40),"Starting Final Project", M22>40, "Prepare for Showcase") -> Prepare for Showcase | S22: TRUE | T22: Zhi En/Zhi Xin - Chumbaka | U22: 1 | W22: 1 | AA22: =sum(V22:Z22) -> 1
A23: 259 | B23: Joelle Lau Lik Ying | C23: Active | D23: 45476 | F23: 2 Wed 7:30-8:30pm | G23: Veritas | H23: Chuan | I23: 45693 | J23: Embedded System | K23: TRUE | M23: =INT((TODAY() - I23) / 7) -> 62 | O23: =IFERROR(__xludf.DUMMYFUNCTION("IFERROR( TEXT( MAX(FILTER(Remark!A:A, TRIM(Remark!B:B) = TRIM(B23))), ""dd/mm/yyyy"" ) & "" - "" & FILTER( Remark!C:C, TRIM(Remark!B:B) = TRIM(B23), Remark!A:A = MAX(FILTER(Remark!A:A, TRIM(Remark!B:B) = TRIM(B23))) ), """" )"),"14/10/2025 - [Caleb] Previously, the student spent some time working on competition projects, but the focus is now back on regular learning. Some of her projects have been completed but not yet submitted. The mentor is advised to remind the student to sub"&"mit all completed projects and to update the parents on her progress.") -> 14/10/2025 - [Caleb] Previously, the student spent some time working on competition projects, but the focus is now back on regular learning. Some of her projects have been completed but not yet submitted. The mentor is advised to remind the student to submit all completed projects and to update the parents on her progress. | P23: =IFERROR(__xludf.DUMMYFUNCTION("TEXTJOIN(CHAR(10), TRUE, IFERROR( FILTER(TEXT(Remark!A:A, ""dd/mm/yyyy"") & "" - "" & Remark!C:C, TRIM(Remark!B:B) = TRIM(B23)), """" ))"),"14/10/2025 - [Caleb] Previously, the student spent some time working on competition projects, but the focus is now back on regular learning. Some of her projects have been completed but not yet submitted. The mentor is advised to remind the student to sub"&"mit all completed projects and to update the parents on her progress.") -> 14/10/2025 - [Caleb] Previously, the student spent some time working on competition projects, but the focus is now back on regular learning. Some of her projects have been completed but not yet submitted. The mentor is advised to remind the student to submit all completed projects and to update the parents on her progress. | Q23: =IFERROR(__xludf.DUMMYFUNCTION("IFERROR( FILTER( Remark!D:D, Remark!A:A = MAX(FILTER(Remark!A:A, TRIM(Remark!B:B) = TRIM(B23))) ), """" )"),"Yes") -> Yes | R23: =IFS(M23<=30, "Learning", AND(M23>30, M23<=40),"Starting Final Project", M23>40, "Prepare for Showcase") -> Prepare for Showcase | S23: TRUE | T23: Joelle/Eugene - Chumbaka | U23: 4 | V23: 1 | X23: 1 | Y23: 1 | AA23: =sum(V23:Z23) -> 3
A24: 260 | B24: Eugene Lau Lik Yang | C24: Active | D24: 45489 | F24: 2 Wed 7:30-8:30pm | G24: Veritas | H24: Chuan | I24: 46029 | J24: AI with Python | K24: TRUE | M24: =INT((TODAY() - I24) / 7) -> 14 | O24: =IFERROR(__xludf.DUMMYFUNCTION("IFERROR( TEXT( MAX(FILTER(Remark!A:A, TRIM(Remark!B:B) = TRIM(B24))), ""dd/mm/yyyy"" ) & "" - "" & FILTER( Remark!C:C, TRIM(Remark!B:B) = TRIM(B24), Remark!A:A = MAX(FILTER(Remark!A:A, TRIM(Remark!B:B) = TRIM(B24))) ), """" )"),"11/11/2025 - [Caleb] The student is currently preparing for the showcase. Demonstrates great initiative and a positive learning attitude, though self-learning skills still need improvement. The mentor team has discussed strategies to support his growth"&". We will begin by asking guiding questions to stimulate critical thinking and help him build problem-solving skills both in Chumbaka and beyond.") -> 11/11/2025 - [Caleb] The student is currently preparing for the showcase. Demonstrates great initiative and a positive learning attitude, though self-learning skills still need improvement. The mentor team has discussed strategies to support his growth. We will begin by asking guiding questions to stimulate critical thinking and help him build problem-solving skills both in Chumbaka and beyond. | P24: =IFERROR(__xludf.DUMMYFUNCTION("TEXTJOIN(CHAR(10), TRUE, IFERROR( FILTER(TEXT(Remark!A:A, ""dd/mm/yyyy"") & "" - "" & Remark!C:C, TRIM(Remark!B:B) = TRIM(B24)), """" ))"),"11/11/2025 - [Caleb] The student is currently preparing for the showcase. Demonstrates great initiative and a positive learning attitude, though self-learning skills still need improvement. The mentor team has discussed strategies to support his growth"&". We will begin by asking guiding questions to stimulate critical thinking and help him build problem-solving skills both in Chumbaka and beyond.") -> 11/11/2025 - [Caleb] The student is currently preparing for the showcase. Demonstrates great initiative and a positive learning attitude, though self-learning skills still need improvement. The mentor team has discussed strategies to support his growth. We will begin by asking guiding questions to stimulate critical thinking and help him build problem-solving skills both in Chumbaka and beyond. | Q24: =IFERROR(__xludf.DUMMYFUNCTION("IFERROR( FILTER( Remark!D:D, Remark!A:A = MAX(FILTER(Remark!A:A, TRIM(Remark!B:B) = TRIM(B24))) ), """" )"),"Yes") -> Yes | R24: =IFS(M24<=30, "Learning", AND(M24>30, M24<=40),"Starting Final Project", M24>40, "Prepare for Showcase") -> Learning | T24: Joelle/Eugene - Chumbaka | U24: 2 | X24: 1 | Y24: 1 | AA24: =sum(V24:Z24) -> 2
A25: 323 | B25: Max Yong Seng Jing | C25: Active | D25: 45717 | F25: 2 Wed 7:30-8:30pm | G25: Veritas | H25: Chuan | I25: 45896 | J25: Creative Computing | K25: TRUE | M25: =INT((TODAY() - I25) / 7) -> 33 | O25: =IFERROR(__xludf.DUMMYFUNCTION("IFERROR( TEXT( MAX(FILTER(Remark!A:A, TRIM(Remark!B:B) = TRIM(B25))), ""dd/mm/yyyy"" ) & "" - "" & FILTER( Remark!C:C, TRIM(Remark!B:B) = TRIM(B25), Remark!A:A = MAX(FILTER(Remark!A:A, TRIM(Remark!B:B) = TRIM(B25))) ), """" )"),"") | P25: =IFERROR(__xludf.DUMMYFUNCTION("TEXTJOIN(CHAR(10), TRUE, IFERROR( FILTER(TEXT(Remark!A:A, ""dd/mm/yyyy"") & "" - "" & Remark!C:C, TRIM(Remark!B:B) = TRIM(B25)), """" ))"),"") | Q25: =IFERROR(__xludf.DUMMYFUNCTION("IFERROR( FILTER( Remark!D:D, Remark!A:A = MAX(FILTER(Remark!A:A, TRIM(Remark!B:B) = TRIM(B25))) ), """" )"),"") | R25: =IFS(M25<=30, "Learning", AND(M25>30, M25<=40),"Starting Final Project", M25>40, "Prepare for Showcase") -> Starting Final Project | T25: Ivan/Max - Chumbaka | U25: 3 | X25: 1 | Y25: 1 | AA25: =sum(V25:Z25) -> 2
A26: 142 | B26: Aaron Ting Kuan Siang | C26: Active | D26: 45119 | F26: 2 Wed 7:30-8:30pm | G26: Veritas | H26: Damian | I26: 45644 | J26: Physical Computing | K26: TRUE | M26: =INT((TODAY() - I26) / 7) -> 69 | O26: No | P26: =IFERROR(__xludf.DUMMYFUNCTION("TEXTJOIN(CHAR(10), TRUE, IFERROR( FILTER(TEXT(Remark!A:A, ""dd/mm/yyyy"") & "" - "" & Remark!C:C, TRIM(Remark!B:B) = TRIM(B26)), """" ))"),"03/10/2025 - [Caleb] Slow learner, often needs to watch twice. Tends to help friends after learning something. Mentor is advised to update the parents and explain the milestones and how we plan to support the student. 06/11/2025 - [Caleb] The mentor has "&"already updated the parents. 10/02/2026 - Aaron is creating a Pong game 🎮. His progress is slow because he likes to teach his friend Benjamin 🌟, and he sometimes needs to watch the tutorial video twice to understand it 💻🚀. 12/02/2026 - Aaron is creat"&"ing a Pong game 🎮. His progress is slow because he likes to teach his friend Benjamin 🌟, and he sometimes needs to watch the tutorial video twice to understand it 💻🚀 06/04/2026 - Aaron is a careful learner 📚 who often benefits from reviewing instruct"&"ional materials more than once to ensure a thorough understanding of the concepts. 💡 He demonstrates a helpful nature by assisting his peers after he has mastered a new topic. 🤝 💻 We will provide regular updates regarding his milestones 🌟 and our plan"&" to support his continued growth. 🚀") -> 03/10/2025 - [Caleb] Slow learner, often needs to watch twice. Tends to help friends after learning something. Mentor is advised to update the parents and explain the milestones and how we plan to support the student. 06/11/2025 - [Caleb] The mentor has already updated the parents. 10/02/2026 - Aaron is creating a Pong game 🎮. His progress is slow because he likes to teach his friend Benjamin 🌟, and he sometimes needs to watch the tutorial video twice to understand it 💻🚀. 12/02/2026 - Aaron is creating a Pong game 🎮. His progress is slow because he likes to teach his friend Benjamin 🌟, and he sometimes needs to watch the tutorial video twice to understand it 💻🚀 06/04/2026 - Aaron is a careful learner 📚 who often benefits from reviewing instructional materials more than once to ensure a thorough understanding of the concepts. 💡 He demonstrates a helpful nature by assisting his peers after he has mastered a new topic. 🤝 💻 We will provide regular updates regarding his milestones 🌟 and our plan to support his continued growth. 🚀 | Q26: Yes | R26: =IFS(M26<=30, "Learning", AND(M26>30, M26<=40),"Starting Final Project", M26>40, "Prepare for Showcase") -> Prepare for Showcase | S26: FALSE | T26: Testing | U26: 5 | V26: 1 | Y26: 1 | AA26: =sum(V26:Z26) -> 2
A27: 179 | B27: Kyle Ling Zhong You | C27: Active | D27: 45175 | F27: 2 Wed 7:30-8:30pm | G27: Veritas | H27: Damian | I27: 45546 | J27: Physical Computing | K27: TRUE | M27: =INT((TODAY() - I27) / 7) -> 83 | O27: =IFERROR(__xludf.DUMMYFUNCTION("IFERROR( TEXT( MAX(FILTER(Remark!A:A, TRIM(Remark!B:B) = TRIM(B27))), ""dd/mm/yyyy"" ) & "" - "" & FILTER( Remark!C:C, TRIM(Remark!B:B) = TRIM(B27), Remark!A:A = MAX(FILTER(Remark!A:A, TRIM(Remark!B:B) = TRIM(B27))) ), """" )"),"") | P27: =IFERROR(__xludf.DUMMYFUNCTION("TEXTJOIN(CHAR(10), TRUE, IFERROR( FILTER(TEXT(Remark!A:A, ""dd/mm/yyyy"") & "" - "" & Remark!C:C, TRIM(Remark!B:B) = TRIM(B27)), """" ))"),"") | Q27: =IFERROR(__xludf.DUMMYFUNCTION("IFERROR( FILTER( Remark!D:D, Remark!A:A = MAX(FILTER(Remark!A:A, TRIM(Remark!B:B) = TRIM(B27))) ), """" )"),"") | R27: =IFS(M27<=30, "Learning", AND(M27>30, M27<=40),"Starting Final Project", M27>40, "Prepare for Showcase") -> Prepare for Showcase | S27: TRUE | T27: Boey/Kyle Ling - Chumbaka | U27: 3 | V27: 1 | AA27: =sum(V27:Z27) -> 1
A28: 282 | B28: Benjamin Lee Zhe Ming | C28: Active | D28: 45520 | F28: 2 Wed 7:30-8:30pm | G28: Veritas | H28: Damian | I28: 45749 | J28: Physical Computing | K28: TRUE | M28: =INT((TODAY() - I28) / 7) -> 54 | O28: =IFERROR(__xludf.DUMMYFUNCTION("IFERROR( TEXT( MAX(FILTER(Remark!A:A, TRIM(Remark!B:B) = TRIM(B28))), ""dd/mm/yyyy"" ) & "" - "" & FILTER( Remark!C:C, TRIM(Remark!B:B) = TRIM(B28), Remark!A:A = MAX(FILTER(Remark!A:A, TRIM(Remark!B:B) = TRIM(B28))) ), """" )"),"06/11/2025 - [Caleb] Some projects were skipped; mentor is advised to update the parents regarding this matter. Student is a slow learner, has progressed up to Project D2.") -> 06/11/2025 - [Caleb] Some projects were skipped; mentor is advised to update the parents regarding this matter. Student is a slow learner, has progressed up to Project D2. | P28: =IFERROR(__xludf.DUMMYFUNCTION("TEXTJOIN(CHAR(10), TRUE, IFERROR( FILTER(TEXT(Remark!A:A, ""dd/mm/yyyy"") & "" - "" & Remark!C:C, TRIM(Remark!B:B) = TRIM(B28)), """" ))"),"06/11/2025 - [Caleb] Some projects were skipped; mentor is advised to update the parents regarding this matter. Student is a slow learner, has progressed up to Project D2.") -> 06/11/2025 - [Caleb] Some projects were skipped; mentor is advised to update the parents regarding this matter. Student is a slow learner, has progressed up to Project D2. | Q28: =IFERROR(__xludf.DUMMYFUNCTION("IFERROR( FILTER( Remark!D:D, Remark!A:A = MAX(FILTER(Remark!A:A, TRIM(Remark!B:B) = TRIM(B28))) ), """" )"),"No") -> No | R28: =IFS(M28<=30, "Learning", AND(M28>30, M28<=40),"Starting Final Project", M28>40, "Prepare for Showcase") -> Prepare for Showcase | S28: FALSE | T28: Benjamin - Chumbaka | U28: 3 | V28: 1 | Y28: 1 | AA28: =sum(V28:Z28) -> 2
A29: 289 | B29: Amarion Hii Lu Ong | C29: Active | D29: 45575 | F29: 2 Wed 7:30-8:30pm | G29: Veritas | H29: Damian | I29: 46029 | J29: Physical Computing | K29: TRUE | M29: =INT((TODAY() - I29) / 7) -> 14 | O29: =IFERROR(__xludf.DUMMYFUNCTION("IFERROR( TEXT( MAX(FILTER(Remark!A:A, TRIM(Remark!B:B) = TRIM(B29))), ""dd/mm/yyyy"" ) & "" - "" & FILTER( Remark!C:C, TRIM(Remark!B:B) = TRIM(B29), Remark!A:A = MAX(FILTER(Remark!A:A, TRIM(Remark!B:B) = TRIM(B29))) ), """" )"),"02/10/2025 - [Caleb] Improved after the mentor spoke to the student personally; the next challenge is to maintain consistent performance.") -> 02/10/2025 - [Caleb] Improved after the mentor spoke to the student personally; the next challenge is to maintain consistent performance. | P29: =IFERROR(__xludf.DUMMYFUNCTION("TEXTJOIN(CHAR(10), TRUE, IFERROR( FILTER(TEXT(Remark!A:A, ""dd/mm/yyyy"") & "" - "" & Remark!C:C, TRIM(Remark!B:B) = TRIM(B29)), """" ))"),"25/09/2025 - [Caleb] Initially, due to a change of mentor, he tended to remain silent for a period of time. He is easily distracted by friends, especially when Benaiah joins the class. The mentor did not provide a specific timeline."" 02/10/2025 - [Caleb]"&" Improved after the mentor spoke to the student personally; the next challenge is to maintain consistent performance.") -> 25/09/2025 - [Caleb] Initially, due to a change of mentor, he tended to remain silent for a period of time. He is easily distracted by friends, especially when Benaiah joins the class. The mentor did not provide a specific timeline." 02/10/2025 - [Caleb] Improved after the mentor spoke to the student personally; the next challenge is to maintain consistent performance. | Q29: =IFERROR(__xludf.DUMMYFUNCTION("IFERROR( FILTER( Remark!D:D, Remark!A:A = MAX(FILTER(Remark!A:A, TRIM(Remark!B:B) = TRIM(B29))) ), """" )"),"Yes") -> Yes | R29: =IFS(M29<=30, "Learning", AND(M29>30, M29<=40),"Starting Final Project", M29>40, "Prepare for Showcase") -> Learning | T29: Amarion - Chumbaka | U29: 4 | V29: 1 | W29: 1 | X29: 1 | Y29: 1 | AA29: =sum(V29:Z29) -> 4
A30: 347 | B30: Noelle Wong Jing Yan | C30: Active | D30: 45782 | F30: 2 Wed 7:30-8:30pm | G30: Veritas | H30: Damian | I30: 45782 | J30: Coding and Algorithm | K30: TRUE | M30: =INT((TODAY() - I30) / 7) -> 49 | O30: =IFERROR(__xludf.DUMMYFUNCTION("IFERROR( TEXT( MAX(FILTER(Remark!A:A, TRIM(Remark!B:B) = TRIM(B30))), ""dd/mm/yyyy"" ) & "" - "" & FILTER( Remark!C:C, TRIM(Remark!B:B) = TRIM(B30), Remark!A:A = MAX(FILTER(Remark!A:A, TRIM(Remark!B:B) = TRIM(B30))) ), """" )"),"") | P30: =IFERROR(__xludf.DUMMYFUNCTION("TEXTJOIN(CHAR(10), TRUE, IFERROR( FILTER(TEXT(Remark!A:A, ""dd/mm/yyyy"") & "" - "" & Remark!C:C, TRIM(Remark!B:B) = TRIM(B30)), """" ))"),"") | Q30: =IFERROR(__xludf.DUMMYFUNCTION("IFERROR( FILTER( Remark!D:D, Remark!A:A = MAX(FILTER(Remark!A:A, TRIM(Remark!B:B) = TRIM(B30))) ), """" )"),"") | R30: =IFS(M30<=30, "Learning", AND(M30>30, M30<=40),"Starting Final Project", M30>40, "Prepare for Showcase") -> Prepare for Showcase | S30: TRUE | T30: Noelle/Faye/Amos - Chumbaka | U30: 2 | V30: 1 | Y30: 1 | AA30: =sum(V30:Z30) -> 2
A31: 23 | B31: Javier Hii Wei Wen | C31: Active | D31: 44568 | F31: 2 Wed 7:30-8:30pm | G31: Veritas | H31: Enouch | I31: 45780 | J31: 3D Design for AR and VR | K31: TRUE | M31: =INT((TODAY() - I31) / 7) -> 50 | O31: =IFERROR(__xludf.DUMMYFUNCTION("IFERROR( TEXT( MAX(FILTER(Remark!A:A, TRIM(Remark!B:B) = TRIM(B31))), ""dd/mm/yyyy"" ) & "" - "" & FILTER( Remark!C:C, TRIM(Remark!B:B) = TRIM(B31), Remark!A:A = MAX(FILTER(Remark!A:A, TRIM(Remark!B:B) = TRIM(B31))) ), """" )"),"") | P31: =IFERROR(__xludf.DUMMYFUNCTION("TEXTJOIN(CHAR(10), TRUE, IFERROR( FILTER(TEXT(Remark!A:A, ""dd/mm/yyyy"") & "" - "" & Remark!C:C, TRIM(Remark!B:B) = TRIM(B31)), """" ))"),"") | Q31: =IFERROR(__xludf.DUMMYFUNCTION("IFERROR( FILTER( Remark!D:D, Remark!A:A = MAX(FILTER(Remark!A:A, TRIM(Remark!B:B) = TRIM(B31))) ), """" )"),"") | R31: =IFS(M31<=30, "Learning", AND(M31>30, M31<=40),"Starting Final Project", M31>40, "Prepare for Showcase") -> Prepare for Showcase | S31: TRUE | T31: Javier - CHUMBAKA | U31: 1 | X31: 1 | Y31: 1 | AA31: =sum(V31:Z31) -> 2
A32: 147 | B32: Evan Sim Teck Yang | C32: Active | D32: 45139 | F32: 2 Wed 7:30-8:30pm | G32: Veritas | H32: Enouch | I32: 46064 | J32: 3D Design for AR and VR | K32: TRUE | M32: =INT((TODAY() - I32) / 7) -> 9 | O32: =IFERROR(__xludf.DUMMYFUNCTION("IFERROR( TEXT( MAX(FILTER(Remark!A:A, TRIM(Remark!B:B) = TRIM(B32))), ""dd/mm/yyyy"" ) & "" - "" & FILTER( Remark!C:C, TRIM(Remark!B:B) = TRIM(B32), Remark!A:A = MAX(FILTER(Remark!A:A, TRIM(Remark!B:B) = TRIM(B32))) ), """" )"),"") | P32: =IFERROR(__xludf.DUMMYFUNCTION("TEXTJOIN(CHAR(10), TRUE, IFERROR( FILTER(TEXT(Remark!A:A, ""dd/mm/yyyy"") & "" - "" & Remark!C:C, TRIM(Remark!B:B) = TRIM(B32)), """" ))"),"") | Q32: =IFERROR(__xludf.DUMMYFUNCTION("IFERROR( FILTER( Remark!D:D, Remark!A:A = MAX(FILTER(Remark!A:A, TRIM(Remark!B:B) = TRIM(B32))) ), """" )"),"") | R32: =IFS(M32<=30, "Learning", AND(M32>30, M32<=40),"Starting Final Project", M32>40, "Prepare for Showcase") -> Learning | T32: Evan Sim - Chumbaka | AA32: =sum(V32:Z32) -> 0
A33: 178 | B33: Boey Ling | C33: Active | D33: 45175 | F33: 2 Wed 7:30-8:30pm | G33: Veritas | H33: Enouch | I33: 45840 | J33: 3D Design for AR and VR | K33: TRUE | M33: =INT((TODAY() - I33) / 7) -> 41 | O33: =IFERROR(__xludf.DUMMYFUNCTION("IFERROR( TEXT( MAX(FILTER(Remark!A:A, TRIM(Remark!B:B) = TRIM(B33))), ""dd/mm/yyyy"" ) & "" - "" & FILTER( Remark!C:C, TRIM(Remark!B:B) = TRIM(B33), Remark!A:A = MAX(FILTER(Remark!A:A, TRIM(Remark!B:B) = TRIM(B33))) ), """" )"),"16/10/2025 - [Caleb] The student previously used the mentor’s laptop during class and was unable to continue progress at home. There were also issues with the student’s MacBook, but the student has recently switched to a Windows laptop last week, which sh"&"ould help improve learning continuity and project progress.") -> 16/10/2025 - [Caleb] The student previously used the mentor’s laptop during class and was unable to continue progress at home. There were also issues with the student’s MacBook, but the student has recently switched to a Windows laptop last week, which should help improve learning continuity and project progress. | P33: =IFERROR(__xludf.DUMMYFUNCTION("TEXTJOIN(CHAR(10), TRUE, IFERROR( FILTER(TEXT(Remark!A:A, ""dd/mm/yyyy"") & "" - "" & Remark!C:C, TRIM(Remark!B:B) = TRIM(B33)), """" ))"),"16/10/2025 - [Caleb] The student previously used the mentor’s laptop during class and was unable to continue progress at home. There were also issues with the student’s MacBook, but the student has recently switched to a Windows laptop last week, which sh"&"ould help improve learning continuity and project progress.") -> 16/10/2025 - [Caleb] The student previously used the mentor’s laptop during class and was unable to continue progress at home. There were also issues with the student’s MacBook, but the student has recently switched to a Windows laptop last week, which should help improve learning continuity and project progress. | Q33: =IFERROR(__xludf.DUMMYFUNCTION("IFERROR( FILTER( Remark!D:D, Remark!A:A = MAX(FILTER(Remark!A:A, TRIM(Remark!B:B) = TRIM(B33))) ), """" )"),"Yes") -> Yes | R33: =IFS(M33<=30, "Learning", AND(M33>30, M33<=40),"Starting Final Project", M33>40, "Prepare for Showcase") -> Prepare for Showcase | T33: Boey/Kyle Ling - Chumbaka | U33: 5 | V33: 1 | X33: 2 | AA33: =sum(V33:Z33) -> 3
A34: 280 | B34: Ngu Hieng Sing | C34: Active | D34: 45489 | F34: 2 Wed 7:30-8:30pm | G34: Veritas | H34: Enouch | I34: 45875 | J34: 3D Design for AR and VR | K34: TRUE | M34: =INT((TODAY() - I34) / 7) -> 36 | O34: =IFERROR(__xludf.DUMMYFUNCTION("IFERROR( TEXT( MAX(FILTER(Remark!A:A, TRIM(Remark!B:B) = TRIM(B34))), ""dd/mm/yyyy"" ) & "" - "" & FILTER( Remark!C:C, TRIM(Remark!B:B) = TRIM(B34), Remark!A:A = MAX(FILTER(Remark!A:A, TRIM(Remark!B:B) = TRIM(B34))) ), """" )"),"") | P34: =IFERROR(__xludf.DUMMYFUNCTION("TEXTJOIN(CHAR(10), TRUE, IFERROR( FILTER(TEXT(Remark!A:A, ""dd/mm/yyyy"") & "" - "" & Remark!C:C, TRIM(Remark!B:B) = TRIM(B34)), """" ))"),"") | Q34: =IFERROR(__xludf.DUMMYFUNCTION("IFERROR( FILTER( Remark!D:D, Remark!A:A = MAX(FILTER(Remark!A:A, TRIM(Remark!B:B) = TRIM(B34))) ), """" )"),"") | R34: =IFS(M34<=30, "Learning", AND(M34>30, M34<=40),"Starting Final Project", M34>40, "Prepare for Showcase") -> Starting Final Project | T34: Hieng Sing - Chumbaka | U34: 1 | W34: 1 | X34: 1 | Y34: 1 | AA34: =sum(V34:Z34) -> 3
A35: 349 | B35: Amos Wong Jun Ren | C35: Active | D35: 45782 | F35: 2 Wed 7:30-8:30pm | G35: Veritas | H35: Enouch | I35: 45782 | J35: Digital Animation | K35: TRUE | M35: =INT((TODAY() - I35) / 7) -> 49 | O35: =IFERROR(__xludf.DUMMYFUNCTION("IFERROR( TEXT( MAX(FILTER(Remark!A:A, TRIM(Remark!B:B) = TRIM(B35))), ""dd/mm/yyyy"" ) & "" - "" & FILTER( Remark!C:C, TRIM(Remark!B:B) = TRIM(B35), Remark!A:A = MAX(FILTER(Remark!A:A, TRIM(Remark!B:B) = TRIM(B35))) ), """" )"),"14/10/2025 - [Caleb] Device (tablet) issue — for example, difficulty with copy and paste. No major issues observed; maintains a positive attitude") -> 14/10/2025 - [Caleb] Device (tablet) issue — for example, difficulty with copy and paste. No major issues observed; maintains a positive attitude | P35: =IFERROR(__xludf.DUMMYFUNCTION("TEXTJOIN(CHAR(10), TRUE, IFERROR( FILTER(TEXT(Remark!A:A, ""dd/mm/yyyy"") & "" - "" & Remark!C:C, TRIM(Remark!B:B) = TRIM(B35)), """" ))"),"14/10/2025 - [Caleb] Device (tablet) issue — for example, difficulty with copy and paste. No major issues observed; maintains a positive attitude") -> 14/10/2025 - [Caleb] Device (tablet) issue — for example, difficulty with copy and paste. No major issues observed; maintains a positive attitude | Q35: =IFERROR(__xludf.DUMMYFUNCTION("IFERROR( FILTER( Remark!D:D, Remark!A:A = MAX(FILTER(Remark!A:A, TRIM(Remark!B:B) = TRIM(B35))) ), """" )"),"Yes") -> Yes | R35: =IFS(M35<=30, "Learning", AND(M35>30, M35<=40),"Starting Final Project", M35>40, "Prepare for Showcase") -> Prepare for Showcase | S35: TRUE | T35: Noelle/Faye/Amos - Chumbaka | U35: 2 | V35: 2 | Y35: 1 | AA35: =sum(V35:Z35) -> 3
A36: 322 | B36: Ivan Yong Seng Feng | C36: Active | D36: 45717 | F36: 2 Wed 7:30-8:30pm | G36: Veritas | H36: Lam | I36: 45721 | J36: Coding and Algorithm | K36: TRUE | M36: =INT((TODAY() - I36) / 7) -> 58 | O36: =IFERROR(__xludf.DUMMYFUNCTION("IFERROR( TEXT( MAX(FILTER(Remark!A:A, TRIM(Remark!B:B) = TRIM(B36))), ""dd/mm/yyyy"" ) & "" - "" & FILTER( Remark!C:C, TRIM(Remark!B:B) = TRIM(B36), Remark!A:A = MAX(FILTER(Remark!A:A, TRIM(Remark!B:B) = TRIM(B36))) ), """" )"),"") | P36: =IFERROR(__xludf.DUMMYFUNCTION("TEXTJOIN(CHAR(10), TRUE, IFERROR( FILTER(TEXT(Remark!A:A, ""dd/mm/yyyy"") & "" - "" & Remark!C:C, TRIM(Remark!B:B) = TRIM(B36)), """" ))"),"") | Q36: =IFERROR(__xludf.DUMMYFUNCTION("IFERROR( FILTER( Remark!D:D, Remark!A:A = MAX(FILTER(Remark!A:A, TRIM(Remark!B:B) = TRIM(B36))) ), """" )"),"") | R36: =IFS(M36<=30, "Learning", AND(M36>30, M36<=40),"Starting Final Project", M36>40, "Prepare for Showcase") -> Prepare for Showcase | S36: TRUE | T36: Ivan/Max - Chumbaka | U36: 3 | V36: 1 | X36: 1 | AA36: =sum(V36:Z36) -> 2
A37: 462 | B37: Richie Louis Chieng Jin Jie | C37: Active | D37: 46085 | F37: 2 Wed 7:30-8:30pm | G37: Veritas | H37: Lam | I37: 46085 | J37: Creative Computing | K37: FALSE | M37: =INT((TODAY() - I37) / 7) -> 6 | O37: =IFERROR(__xludf.DUMMYFUNCTION("IFERROR( TEXT( MAX(FILTER(Remark!A:A, TRIM(Remark!B:B) = TRIM(B37))), ""dd/mm/yyyy"" ) & "" - "" & FILTER( Remark!C:C, TRIM(Remark!B:B) = TRIM(B37), Remark!A:A = MAX(FILTER(Remark!A:A, TRIM(Remark!B:B) = TRIM(B37))) ), """" )"),"") | P37: =IFERROR(__xludf.DUMMYFUNCTION("TEXTJOIN(CHAR(10), TRUE, IFERROR( FILTER(TEXT(Remark!A:A, ""dd/mm/yyyy"") & "" - "" & Remark!C:C, TRIM(Remark!B:B) = TRIM(B37)), """" ))"),"") | Q37: =IFERROR(__xludf.DUMMYFUNCTION("IFERROR( FILTER( Remark!D:D, Remark!A:A = MAX(FILTER(Remark!A:A, TRIM(Remark!B:B) = TRIM(B37))) ), """" )"),"") | R37: =IFS(M37<=30, "Learning", AND(M37>30, M37<=40),"Starting Final Project", M37>40, "Prepare for Showcase") -> Learning | S37: FALSE | T37: Richie Louis - Chumbaka | Y37: 1 | AA37: =sum(V37:Z37) -> 1
A38: 348 | B38: Faye Wong Jing Tong | C38: Active | D38: 45782 | F38: 2 Wed 7:30-8:30pm | G38: Veritas | H38: Mandy | I38: 45782 | J38: Mobile Coding | K38: TRUE | M38: =INT((TODAY() - I38) / 7) -> 49 | N38: Mobile Coding Showcase | O38: =IFERROR(__xludf.DUMMYFUNCTION("IFERROR( TEXT( MAX(FILTER(Remark!A:A, TRIM(Remark!B:B) = TRIM(B38))), ""dd/mm/yyyy"" ) & "" - "" & FILTER( Remark!C:C, TRIM(Remark!B:B) = TRIM(B38), Remark!A:A = MAX(FILTER(Remark!A:A, TRIM(Remark!B:B) = TRIM(B38))) ), """" )"),"") | P38: =IFERROR(__xludf.DUMMYFUNCTION("TEXTJOIN(CHAR(10), TRUE, IFERROR( FILTER(TEXT(Remark!A:A, ""dd/mm/yyyy"") & "" - "" & Remark!C:C, TRIM(Remark!B:B) = TRIM(B38)), """" ))"),"") | Q38: =IFERROR(__xludf.DUMMYFUNCTION("IFERROR( FILTER( Remark!D:D, Remark!A:A = MAX(FILTER(Remark!A:A, TRIM(Remark!B:B) = TRIM(B38))) ), """" )"),"") | R38: =IFS(M38<=30, "Learning", AND(M38>30, M38<=40),"Starting Final Project", M38>40, "Prepare for Showcase") -> Prepare for Showcase | S38: TRUE | T38: Noelle/Faye/Amos - Chumbaka | U38: 3 | V38: 2 | W38: 1 | Y38: 1 | AA38: =sum(V38:Z38) -> 4
A39: 418 | B39: Ethan Tan Jun Han | C39: Active | D39: 46034 | F39: 2 Wed 7:30-8:30pm | G39: Veritas | H39: Mandy | I39: 46036 | J39: Mobile Coding | K39: FALSE | L39: New Student | M39: =INT((TODAY() - I39) / 7) -> 13 | O39: =IFERROR(__xludf.DUMMYFUNCTION("IFERROR( TEXT( MAX(FILTER(Remark!A:A, TRIM(Remark!B:B) = TRIM(B39))), ""dd/mm/yyyy"" ) & "" - "" & FILTER( Remark!C:C, TRIM(Remark!B:B) = TRIM(B39), Remark!A:A = MAX(FILTER(Remark!A:A, TRIM(Remark!B:B) = TRIM(B39))) ), """" )"),"") | P39: =IFERROR(__xludf.DUMMYFUNCTION("TEXTJOIN(CHAR(10), TRUE, IFERROR( FILTER(TEXT(Remark!A:A, ""dd/mm/yyyy"") & "" - "" & Remark!C:C, TRIM(Remark!B:B) = TRIM(B39)), """" ))"),"") | Q39: =IFERROR(__xludf.DUMMYFUNCTION("IFERROR( FILTER( Remark!D:D, Remark!A:A = MAX(FILTER(Remark!A:A, TRIM(Remark!B:B) = TRIM(B39))) ), """" )"),"") | R39: =IFS(M39<=30, "Learning", AND(M39>30, M39<=40),"Starting Final Project", M39>40, "Prepare for Showcase") -> Learning | T39: Ethan Tan - Chumbaka | V39: 2 | W39: 1 | X39: 1 | Y39: 1 | AA39: =sum(V39:Z39) -> 5
A40: 455 | B40: Ian Yung Yi En | C40: Active | D40: 46083 | F40: 2 Wed 7:30-8:30pm | G40: Veritas | H40: Mandy | I40: 46083 | J40: Mobile Coding | K40: FALSE | M40: =INT((TODAY() - I40) / 7) -> 6 | O40: =IFERROR(__xludf.DUMMYFUNCTION("IFERROR( TEXT( MAX(FILTER(Remark!A:A, TRIM(Remark!B:B) = TRIM(B40))), ""dd/mm/yyyy"" ) & "" - "" & FILTER( Remark!C:C, TRIM(Remark!B:B) = TRIM(B40), Remark!A:A = MAX(FILTER(Remark!A:A, TRIM(Remark!B:B) = TRIM(B40))) ), """" )"),"") | P40: =IFERROR(__xludf.DUMMYFUNCTION("TEXTJOIN(CHAR(10), TRUE, IFERROR( FILTER(TEXT(Remark!A:A, ""dd/mm/yyyy"") & "" - "" & Remark!C:C, TRIM(Remark!B:B) = TRIM(B40)), """" ))"),"") | Q40: =IFERROR(__xludf.DUMMYFUNCTION("IFERROR( FILTER( Remark!D:D, Remark!A:A = MAX(FILTER(Remark!A:A, TRIM(Remark!B:B) = TRIM(B40))) ), """" )"),"") | R40: =IFS(M40<=30, "Learning", AND(M40>30, M40<=40),"Starting Final Project", M40>40, "Prepare for Showcase") -> Learning | S40: FALSE | T40: Ian/Abigail - Chumbaka | X40: 2 | Y40: 1 | AA40: =sum(V40:Z40) -> 3
...

Sheet Replacement
A1: =IFERROR(__xludf.DUMMYFUNCTION("IMPORTRANGE(""https://docs.google.com/spreadsheets/d/1M-AMmjvFdeyUY8R05cLsAzA8EFTTNWQbDnacxXDTUb8/edit?usp=sharing"", ""Replacement!A:Z"")"),"")
A4: =IFERROR(__xludf.DUMMYFUNCTION("""COMPUTED_VALUE"""),"Student Name") -> Student Name | B4: =IFERROR(__xludf.DUMMYFUNCTION("""COMPUTED_VALUE"""),"Replacement Date") -> Replacement Date | C4: =IFERROR(__xludf.DUMMYFUNCTION("""COMPUTED_VALUE"""),"Time Slot (for Saturdays)") -> Time Slot (for Saturdays) | D4: =IFERROR(__xludf.DUMMYFUNCTION("""COMPUTED_VALUE"""),"Email") -> Email | E4: =IFERROR(__xludf.DUMMYFUNCTION("""COMPUTED_VALUE"""),"Submission Timestamp") -> Submission Timestamp
A5: =IFERROR(__xludf.DUMMYFUNCTION("""COMPUTED_VALUE"""),"Eileen Wong Hui Qing") -> Eileen Wong Hui Qing | B5: =IFERROR(__xludf.DUMMYFUNCTION("""COMPUTED_VALUE"""),46029.0) -> 46029 | D5: =IFERROR(__xludf.DUMMYFUNCTION("""COMPUTED_VALUE"""),"paksien79@yahoo.com") -> paksien79@yahoo.com | E5: =IFERROR(__xludf.DUMMYFUNCTION("""COMPUTED_VALUE"""),46028.902648703704) -> 46028.903
A6: =IFERROR(__xludf.DUMMYFUNCTION("""COMPUTED_VALUE"""),"Eunice Wong Shi Qing") -> Eunice Wong Shi Qing | B6: =IFERROR(__xludf.DUMMYFUNCTION("""COMPUTED_VALUE"""),46029.0) -> 46029 | D6: =IFERROR(__xludf.DUMMYFUNCTION("""COMPUTED_VALUE"""),"paksien79@yahoo.com") -> paksien79@yahoo.com | E6: =IFERROR(__xludf.DUMMYFUNCTION("""COMPUTED_VALUE"""),46028.902684479166) -> 46028.903
A7: =IFERROR(__xludf.DUMMYFUNCTION("""COMPUTED_VALUE"""),"Ryan Sia Rui Eng") -> Ryan Sia Rui Eng | B7: =IFERROR(__xludf.DUMMYFUNCTION("""COMPUTED_VALUE"""),46032.0) -> 46032 | C7: =IFERROR(__xludf.DUMMYFUNCTION("""COMPUTED_VALUE"""),"10am - 11am") -> 10am - 11am | D7: =IFERROR(__xludf.DUMMYFUNCTION("""COMPUTED_VALUE"""),"mlyii@hotmail.com") -> mlyii@hotmail.com | E7: =IFERROR(__xludf.DUMMYFUNCTION("""COMPUTED_VALUE"""),46031.834884571756) -> 46031.835
